Workbook

Sheet Cover
B6: Practical Skills Module: Financial Modeling
B12: Blu Containers Company
B13: =TODAY() -> 46215
B24: Financial Model Worksheet - Vertical Orientation | H24: Powered by:

Sheet Summary
B1: =Cover!B12 -> Blu Containers Company
B2: Summary Outputs
C5: SUMMARY VALUES - BASE CASE | T5: ="SUMMMARY VALUES - "&UPPER(CHOOSE(Scenarios!$D$6,Scenarios!C14,Scenarios!C15,Scenarios!C16)) -> SUMMMARY VALUES - BASE CASE
K6: Projected | AA6: Projected
D7: ($ Millions) | F7: Trend | H7: =X7 -> 2020 | I7: =Y7 -> 2021 | J7: =Z7 -> 2022 | K7: =AA7 -> 2023 | L7: =AB7 -> 2024 | M7: =AC7 -> 2025 | N7: =AD7 -> 2026 | O7: =AE7 -> 2027 | X7: =Model!H7 -> 2020 | Y7: =Model!I7 -> 2021 | Z7: =Model!J7 -> 2022 | AA7: =Model!K7 -> 2023 | AB7: =Model!L7 -> 2024 | AC7: =Model!M7 -> 2025 | AD7: =Model!N7 -> 2026 | AE7: =Model!O7 -> 2027
D10: Income Statement Items | U10: Income Statement Items
E12: Net Revenue | H12: 213.5 | I12: 236.6 | J12: 204.8 | K12: 252.4621 | L12: 233.58111 | M12: 281.23111 | N12: 281.22955 | O12: 268.17287 | V12: Net Revenue | W12: (MM) | X12: =Model!H85 -> 213.5 | Y12: =Model!I85 -> 236.6 | Z12: =Model!J85 -> 204.8 | AA12: =Model!K85 -> 252.4621 | AB12: =Model!L85 -> 233.58111 | AC12: =Model!M85 -> 281.23111 | AD12: =Model!N85 -> 281.22955 | AE12: =Model!O85 -> 268.17287
E13: Growth | I13: 0.10819672 | J13: -0.13440406 | K13: 0.23272508 | L13: -0.074787393 | M13: 0.20399763 | N13: -5.5263805e-06 | O13: -0.04642714 | V13: Growth | W13: (%) | Y13: =Y12/X12-1 -> 0.10819672 | Z13: =Z12/Y12-1 -> -0.13440406 | AA13: =AA12/Z12-1 -> 0.23272508 | AB13: =AB12/AA12-1 -> -0.074787393 | AC13: =AC12/AB12-1 -> 0.20399763 | AD13: =AD12/AC12-1 -> -5.5263805e-06 | AE13: =AE12/AD12-1 -> -0.04642714
E16: EBITDA | H16: 50.2 | I16: 68.4 | J16: 33.1 | K16: 73.875242 | L16: 47.110499 | M16: 86.456886 | N16: 76.709885 | O16: 54.342096 | V16: EBITDA | W16: (MM) | X16: =Model!H92 -> 50.2 | Y16: =Model!I92 -> 68.4 | Z16: =Model!J92 -> 33.1 | AA16: =Model!K92 -> 73.875242 | AB16: =Model!L92 -> 47.110499 | AC16: =Model!M92 -> 86.456886 | AD16: =Model!N92 -> 76.709885 | AE16: =Model!O92 -> 54.342096
E17: Margin | H17: 0.23512881 | I17: 0.28909552 | J17: 0.16162109 | K17: 0.29261914 | L17: 0.20168796 | M17: 0.30742291 | N17: 0.27276609 | O17: 0.2026383 | V17: Margin | W17: (%) | X17: =X16/X12 -> 0.23512881 | Y17: =Y16/Y12 -> 0.28909552 | Z17: =Z16/Z12 -> 0.16162109 | AA17: =AA16/AA12 -> 0.29261914 | AB17: =AB16/AB12 -> 0.20168796 | AC17: =AC16/AC12 -> 0.30742291 | AD17: =AD16/AD12 -> 0.27276609 | AE17: =AE16/AE12 -> 0.2026383
E18: Growth | I18: 0.3625498 | J18: -0.51608187 | K18: 1.2318804 | L18: -0.36229652 | M18: 0.83519358 | N18: -0.11273829 | O18: -0.29158939 | V18: Growth | W18: (%) | Y18: =Y16/X16-1 -> 0.3625498 | Z18: =Z16/Y16-1 -> -0.51608187 | AA18: =AA16/Z16-1 -> 1.2318804 | AB18: =AB16/AA16-1 -> -0.36229652 | AC18: =AC16/AB16-1 -> 0.83519358 | AD18: =AD16/AC16-1 -> -0.11273829 | AE18: =AE16/AD16-1 -> -0.29158939
E21: Net Income | H21: 14.1 | I21: 23.7 | J21: 2.2 | K21: 29.705374 | L21: 12.883787 | M21: 38.802359 | N21: 33.318879 | O21: 19.418162 | V21: Net Income | W21: (MM) | X21: =Model!H104 -> 14.1 | Y21: =Model!I104 -> 23.7 | Z21: =Model!J104 -> 2.2 | AA21: =Model!K104 -> 29.705374 | AB21: =Model!L104 -> 12.883787 | AC21: =Model!M104 -> 38.802359 | AD21: =Model!N104 -> 33.318879 | AE21: =Model!O104 -> 19.418162
E22: Margin | H22: 0.066042155 | I22: 0.10016906 | J22: 0.010742187 | K22: 0.11766271 | L22: 0.055157659 | M22: 0.13797321 | N22: 0.11847574 | O22: 0.072409123 | V22: Margin | W22: (%) | X22: =X21/X12 -> 0.066042155 | Y22: =Y21/Y12 -> 0.10016906 | Z22: =Z21/Z12 -> 0.010742187 | AA22: =AA21/AA12 -> 0.11766271 | AB22: =AB21/AB12 -> 0.055157659 | AC22: =AC21/AC12 -> 0.13797321 | AD22: =AD21/AD12 -> 0.11847574 | AE22: =AE21/AE12 -> 0.072409123
E23: Growth | I23: 0.68085106 | J23: -0.907173 | K23: 12.502443 | L23: -0.56628092 | M23: 2.0117199 | N23: -0.14131822 | O23: -0.41720241 | V23: Growth | W23: (%) | Y23: =Y21/X21-1 -> 0.68085106 | Z23: =Z21/Y21-1 -> -0.907173 | AA23: =AA21/Z21-1 -> 12.502443 | AB23: =AB21/AA21-1 -> -0.56628092 | AC23: =AC21/AB21-1 -> 2.0117199 | AD23: =AD21/AC21-1 -> -0.14131822 | AE23: =AE21/AD21-1 -> -0.41720241
U25: Balance sheet
C26: SUMMARY VALUES - BEST CASE | V26: Senior Secured Term Debt | W26: (MM) | X26: =Model!H177 -> 250 | Y26: =Model!I177 -> 225 | Z26: =Model!J177 -> 200 | AA26: =Model!K177 -> 175 | AB26: =Model!L177 -> 150 | AC26: =Model!M177 -> 125 | AD26: =Model!N177 -> 100 | AE26: =Model!O177 -> 75
K27: Projected | V27: Growth | W27: (%) | Y27: =Y26/X26-1 -> -0.1 | Z27: =Z26/Y26-1 -> -0.11111111 | AA27: =AA26/Z26-1 -> -0.125 | AB27: =AB26/AA26-1 -> -0.14285714 | AC27: =AC26/AB26-1 -> -0.16666667 | AD27: =AD26/AC26-1 -> -0.2 | AE27: =AE26/AD26-1 -> -0.25
D28: ($ Millions) | F28: Trend | H28: =H7 -> 2020 | I28: =I7 -> 2021 | J28: =J7 -> 2022 | K28: =K7 -> 2023 | L28: =L7 -> 2024 | M28: =M7 -> 2025 | N28: =N7 -> 2026 | O28: =O7 -> 2027 | V28: Bank Debt - Revolver | W28: (MM) | X28: =Model!H171 -> 0 | Y28: =Model!I171 -> 0 | Z28: =Model!J171 -> 0 | AA28: =Model!K171 -> 1.0770176 | AB28: =Model!L171 -> 7.7435851 | AC28: =Model!M171 -> 1.2289546 | AD28: =Model!N171 -> 0 | AE28: =Model!O171 -> 2.6139756
V29: Growth | W29: (%) | Y29: =IFERROR(Y28/X28-1, "") | Z29: =IFERROR(Z28/Y28-1, "") | AA29: =IFERROR(AA28/Z28-1, "") | AB29: =IFERROR(AB28/AA28-1, "") -> 6.1898407 | AC29: =IFERROR(AC28/AB28-1, "") -> -0.84129384 | AD29: =IFERROR(AD28/AC28-1, "") -> -1 | AE29: =IFERROR(AE28/AD28-1, "")
D31: Income Statement Items | V31: Shareholder's Equity | W31: (MM) | X31: =Model!H184 -> 239.7 | Y31: =Model!I184 -> 258.7 | Z31: =Model!J184 -> 258.5 | AA31: =Model!K184 -> 282.2643 | AB31: =Model!L184 -> 292.57133 | AC31: =Model!M184 -> 323.61322 | AD31: =Model!N184 -> 350.26832 | AE31: =Model!O184 -> 365.80285
V32: Growth | W32: (%) | Y32: =Y31/X31-1 -> 0.079265749 | Z32: =Z31/Y31-1 -> -0.00077309625 | AA32: =AA31/Z31-1 -> 0.091931525 | AB32: =AB31/AA31-1 -> 0.036515528 | AC32: =AC31/AB31-1 -> 0.10610024 | AD32: =AD31/AC31-1 -> 0.082367165 | AE32: =AE31/AD31-1 -> 0.044350371
E33: Net Revenue | H33: 213.5 | I33: 236.6 | J33: 204.8 | K33: 264.10863 | L33: 244.64312 | M33: 297.21532 | N33: 300.41838 | O33: 281.50084
E34: Growth | I34: 0.10819672 | J34: -0.13440406 | K34: 0.28959292 | L34: -0.073702679 | M34: 0.21489344 | N34: 0.010776922 | O34: -0.062970636
E37: EBITDA | H37: 50.2 | I37: 68.4 | J37: 33.1 | K37: 85.521774 | L37: 58.538129 | M37: 102.0651 | N37: 95.265445 | O37: 70.580713
E38: Margin | H38: 0.23512881 | I38: 0.28909552 | J38: 0.16162109 | K38: 0.32381287 | L38: 0.23927969 | M38: 0.34340456 | N38: 0.31710924 | O38: 0.25073002
E39: Growth | I39: 0.3625498 | J39: -0.51608187 | K39: 1.5837394 | L39: -0.31551784 | M39: 0.74356608 | N39: -0.066620723 | O39: -0.25911528
E42: Net Income | H42: 14.1 | I42: 23.7 | J42: 2.2 | K42: 37.27562 | L42: 20.35375 | M42: 49.249695 | N42: 45.427923 | O42: 29.973263
E43: Margin | H43: 0.066042155 | I43: 0.10016906 | J43: 0.010742187 | K43: 0.14113746 | L43: 0.083197723 | M43: 0.16570376 | N43: 0.15121552 | O43: 0.10647664
E44: Growth | I44: 0.68085106 | J44: -0.907173 | K44: 15.943464 | L44: -0.45396615 | M44: 1.4196865 | N44: -0.077599927 | O44: -0.34020176
C47: SUMMARY VALUES - WORST CASE
K48: Projected
D49: ($ Millions) | F49: Trend | H49: =H28 -> 2020 | I49: =I28 -> 2021 | J49: =J28 -> 2022 | K49: =K28 -> 2023 | L49: =L28 -> 2024 | M49: =M28 -> 2025 | N49: =N28 -> 2026 | O49: =O28 -> 2027
D52: Income Statement Items
E53: Net Revenue | H53: 213.5 | I53: 236.6 | J53: 204.8 | K53: 238.41461 | L53: 220.17079 | M53: 262.60854 | N53: 259.93619 | O53: 244.66998
E54: Growth | I54: 0.10819672 | J54: -0.13440406 | K54: 0.16413383 | L54: -0.076521412 | M54: 0.19274926 | N54: -0.010176171 | O54: -0.058730611
E57: EBITDA | H57: 50.2 | I57: 68.4 | J57: 33.1 | K57: 60.834295 | L57: 33.859072 | M57: 68.207666 | N57: 57.052628 | O57: 34.164574
E58: Margin | H58: 0.23512881 | I58: 0.28909552 | J58: 0.16162109 | K58: 0.25516178 | L58: 0.15378549 | M58: 0.25973133 | N58: 0.21948705 | O58: 0.13963533
E59: Growth | I59: 0.3625498 | J59: -0.51608187 | K59: 0.83789411 | L59: -0.44342132 | M59: 1.0144577 | N59: -0.16354523 | O59: -0.40117441
E62: Net Income | H62: 14.1 | I62: 23.7 | J62: 2.2 | K62: 21.228758 | L62: 4.0836355 | M62: 26.465119 | N62: 19.699196 | O62: 5.1078377
E63: Margin | H63: 0.066042155 | I63: 0.10016906 | J63: 0.010742187 | K63: 0.089041349 | L63: 0.018547581 | M63: 0.10077783 | N63: 0.075784738 | O63: 0.020876438
...

Sheet Assumptions
B1: =Cover!B12 -> Blu Containers Company
B2: Inputs and Assumptions
C5: GENERAL | J5: EQUITY
C8: - | D8: First year of forecast in financial model: | G8: 2023 | J8: ="Stock Price - "&TEXT(TODAY()-1,"mm/dd/yy") -> Stock Price - 07/dd/yy | N8: 11.5
C9: - | D9: Three scenarios have been used for Inflation, Product Pricing | J9: ="Fully Diluted Shares O/S (MM) - Dec. 31, "&G8-1 -> Fully Diluted Shares O/S (MM) - Dec. 31, 2022 | N9: 14.8
D10: and sales volume growth | J10: Common Dividend Payout Rate | N10: 0.2
C13: PRODUCT PRICING | J13: OPERATIONS
C16: - | D16: The product pricing cases used in the model are as follows:
C17: Pricing Case | E17: =Scenarios!G6&" - "&Scenarios!K6 -> 2023 - 2027 | J17: Annual Factory Capacity (000's units): | N17: 420
C18: Base Case | E18: Research Forecast
C19: Best Case | F19: 0.04 | J19: Capacity Constraints - reached opearting rate | N19: =MAX(Model!O22) -> 1 | O19: conditional formating
C20: Worst Case | F20: -0.04
C23: COSTS | J23: INTEREST RATES
C26: Cost Item | E26: =G8 -> 2023 | G26: Increases
C27: Raw Materials | E27: 226 | F27: per Unit | G27: Inflation on a unit basis | J27: Interest earned on Cash balances: | N27: 0.01
C28: Utilities | E28: 66.2 | F28: per Unit | G28: Inflation on a unit basis | J28: Interest rate on Bank Revolver: | N28: 0.06
C29: Rent | E29: 23.5 | F29: MM | G29: Inflation on a total basis | J29: Interest rate on Senior Secured Term Debt: | N29: 0.06
C30: Operating Labour | E30: 43.5 | F30: MM | G30: Inflation on a total basis
C31: Other | E31: 2 | F31: MM | G31: Inflation on a total basis
C32: SG&A | E32: 3.9 | F32: MM | G32: Inflation on a total basis
C35: DEPRECIATION | J35: TAXES
C38: - | D38: Depreciation Methodology Used: | H38: Straight Line
C39: - | D39: Years remaining for depreciation of existing assets: | H39: 25 | J39: Tax rate assumed in the model: | N39: 0.35
C40: - | D40: Years used for depreciation of new assets: | H40: 30 | J40: Additional tax assumptions in "Other Assumptions" box
B44: =Summary!B1 -> Blu Containers Company
B45: Inputs and Assumptions
C48: OTHER ASSUMPTIONS | J48: =G8 -> 2023 | K48: =J48+1 -> 2024 | L48: =K48+1 -> 2025 | M48: =L48+1 -> 2026 | N48: =M48+1 -> 2027
C52: Income Statement
D53: Cost Adjustments - Gain/(Loss) | G53: MM | J53: 0 | K53: 0 | L53: 0 | M53: 0 | N53: 0
C55: Cash Flow Statement
D56: Investing Activities - Other | G56: MM | J56: 0 | K56: 0 | L56: 0 | M56: 0 | N56: 0
C58: Capital Expenditures | G58: MM | J58: 16 | K58: 17 | L58: 17.3 | M58: 17.5 | N58: 18
C60: Income Tax
D61: Reduction in EBT for timing differences | G61: MM | J61: 5 | K61: 5 | L61: 5 | M61: 5 | N61: 5
C63: Working Capital Days
D64: Accounts Receivable | G64: days | J64: 48 | K64: 44 | L64: 40 | M64: 40 | N64: 40
D65: Inventories | G65: days | J65: 70 | K65: 65 | L65: 60 | M65: 60 | N65: 55
D66: Prepaid Expenses | G66: days | J66: 30 | K66: 30 | L66: 30 | M66: 30 | N66: 30
D67: Other Assets | G67: days | J67: 3 | K67: 3 | L67: 3 | M67: 3 | N67: 3
D68: Accounts Payable | G68: days | J68: 40 | K68: 40 | L68: 40 | M68: 40 | N68: 40
...

Sheet Scenarios
B1: =Assumptions!B1 -> Blu Containers Company
B2: Economic and Sales Scenarios
B6: SCENARIO SWITCH: | D6: 1 | G6: =Assumptions!G8 -> 2023 | H6: =G6+1 -> 2024 | I6: =H6+1 -> 2025 | J6: =I6+1 -> 2026 | K6: =J6+1 -> 2027
D9: Base Case
B10: ECONOMIC SCENARIOS
B12: Cost Inflation | D12: LIVE CASE -> | G12: =CHOOSE($D$6,G14,G15,G16) -> 0.02 | H12: =CHOOSE($D$6,H14,H15,H16) -> 0.02 | I12: =CHOOSE($D$6,I14,I15,I16) -> 0.02 | J12: =CHOOSE($D$6,J14,J15,J16) -> 0.025 | K12: =CHOOSE($D$6,K14,K15,K16) -> 0.025
C14: =Assumptions!C18 -> Base Case | D14: step1 | G14: 0.02 | H14: 0.02 | I14: 0.02 | J14: 0.025 | K14: 0.025
C15: =Assumptions!C19 -> Best Case | D15: inputs | G15: 0.018 | H15: 0.018 | I15: 0.018 | J15: 0.02 | K15: 0.02
C16: =Assumptions!C20 -> Worst Case | D16: blue | G16: 0.025 | H16: 0.025 | I16: 0.025 | J16: 0.025 | K16: 0.025
B21: SALES SCENARIOS
B23: Sales Price - $/Unit | G23: =CHOOSE($D$6,G25,G26,G27) -> 800 | H23: =CHOOSE($D$6,H25,H26,H27) -> 725 | I23: =CHOOSE($D$6,I25,I26,I27) -> 825 | J23: =CHOOSE($D$6,J25,J26,J27) -> 800 | K23: =CHOOSE($D$6,K25,K26,K27) -> 750
C25: =C14 -> Base Case | G25: 800 | H25: 725 | I25: 825 | J25: 800 | K25: 750
A26: =Assumptions!F19 -> 0.04 | C26: =C15 -> Best Case | G26: =G25*(1+$A26) -> 832 | H26: =H25*(1+$A26) -> 754 | I26: =I25*(1+$A26) -> 858 | J26: =J25*(1+$A26) -> 832 | K26: =K25*(1+$A26) -> 780
A27: =Assumptions!F20 -> -0.04 | C27: =C16 -> Worst Case | G27: =G25*(1+$A27) -> 768 | H27: =H25*(1+$A27) -> 696 | I27: =I25*(1+$A27) -> 792 | J27: =J25*(1+$A27) -> 768 | K27: =K25*(1+$A27) -> 720
B30: Sales Volume Growth | G30: =CHOOSE($D$6,G32,G33,G34) -> 0.05 | H30: =CHOOSE($D$6,H32,H33,H34) -> 0.04 | I30: =CHOOSE($D$6,I32,I33,I34) -> 0.04 | J30: =CHOOSE($D$6,J32,J33,J34) -> 0.04 | K30: =CHOOSE($D$6,K32,K33,K34) -> 0.04
C32: =C14 -> Base Case | G32: 0.05 | H32: 0.04 | I32: 0.04 | J32: 0.04 | K32: 0.04
C33: =C15 -> Best Case | G33: 0.05 | H33: 0.04 | I33: 0.05 | J33: 0.05 | K33: 0.04
C34: =C16 -> Worst Case | G34: 0.04 | H34: 0.04 | I34: 0.03 | J34: 0.03 | K34: 0.02

Sheet Model
O1: ="Currently Running : "&CHOOSE(Scenarios!$D$6,Scenarios!C14,Scenarios!C15,Scenarios!C16)&" Scenario" -> Currently Running : Base Case Scenario
B2: =Scenarios!B1 -> Blu Containers Company
B3: Revenue Schedule
H6: Historical data | K6: Projected
F7: Units | H7: =I7-1 -> 2020 | I7: =J7-1 -> 2021 | J7: =K7-1 -> 2022 | K7: =Scenarios!G6 -> 2023 | L7: =Scenarios!H6 -> 2024 | M7: =Scenarios!I6 -> 2025 | N7: =Scenarios!J6 -> 2026 | O7: =Scenarios!K6 -> 2027
B9: Pricing
C10: Gross Sales Price | F10: ($/unit) | J10: 694.4 | K10: =Scenarios!G23 -> 800 | L10: =Scenarios!H23 -> 725 | M10: =Scenarios!I23 -> 825 | N10: =Scenarios!J23 -> 800 | O10: =Scenarios!K23 -> 750
C11: Cost Inflation | F11: (%) | K11: =Scenarios!G12 -> 0.02 | L11: =Scenarios!H12 -> 0.02 | M11: =Scenarios!I12 -> 0.02 | N11: =Scenarios!J12 -> 0.025 | O11: =Scenarios!K12 -> 0.025
C12: Freight & Warehousing | F12: ($/unit) | J12: 100 | K12: =J12*(1+K11) -> 102 | L12: =K12*(1+L11) -> 104.04 | M12: =L12*(1+M11) -> 106.1208 | N12: =M12*(1+N11) -> 108.77382 | O12: =N12*(1+O11) -> 111.49317
C13: Net Sales Price | F13: ($/unit) | J13: =J10-J12 -> 594.4 | K13: =K10-K12 -> 698 | L13: =L10-L12 -> 620.96 | M13: =M10-M12 -> 718.8792 | N13: =N10-N12 -> 691.22618 | O13: =O10-O12 -> 638.50683
B16: Sales Volume
C17: Annual Factory Capacity | F17: (000's units) | K17: =Assumptions!N17 -> 420 | L17: =K17 -> 420 | M17: =L17 -> 420 | N17: =M17 -> 420 | O17: =N17 -> 420
C19: Sales Volume Growth | F19: (%) | K19: =Scenarios!G30 -> 0.05 | L19: =Scenarios!H30 -> 0.04 | M19: =Scenarios!I30 -> 0.04 | N19: =Scenarios!J30 -> 0.04 | O19: =Scenarios!K30 -> 0.04
C20: Annual Sales Volume | F20: (000's units) | J20: =J26*1000/J10 -> 344.47005 | K20: =MIN(J20*(K19+1),K17) -> 361.69355 | L20: =MIN(K20*(L19+1),L17) -> 376.16129 | M20: =MIN(L20*(M19+1),M17) -> 391.20774 | N20: =MIN(M20*(N19+1),N17) -> 406.85605 | O20: =MIN(N20*(O19+1),O17) -> 420
C22: Implied Operating Rate | K22: =K20/K17 -> 0.86117512 | L22: =L20/L17 -> 0.89562212 | M22: =M20/M17 -> 0.931447 | N22: =N20/N17 -> 0.96870488 | O22: =O20/O17 -> 1
B25: Revenue
C26: Gross Revenue | F26: ($ MM) | J26: =J83 -> 239.2 | K26: =(K10*K20)/1000 -> 289.35484 | L26: =(L10*L20)/1000 -> 272.71694 | M26: =(M10*M20)/1000 -> 322.74639 | N26: =(N10*N20)/1000 -> 325.48484 | O26: =(O10*O20)/1000 -> 315
C27: Freight & Warehousing | F27: ($ MM) | J27: =J84 -> 34.4 | K27: =(K12*K20)/1000 -> 36.892742 | L27: =(L12*L20)/1000 -> 39.135821 | M27: =(M12*M20)/1000 -> 41.515279 | N27: =(N12*N20)/1000 -> 44.255287 | O27: =(O12*O20)/1000 -> 46.82713
C28: Net Revenue | F28: ($ MM) | J28: =J26-J27 -> 204.8 | K28: =K26-K27 -> 252.4621 | L28: =L26-L27 -> 233.58111 | M28: =M26-M27 -> 281.23111 | N28: =N26-N27 -> 281.22955 | O28: =O26-O27 -> 268.17287
O31: =$O$1 -> Currently Running : Base Case Scenario
B32: =B$2 -> Blu Containers Company
B33: Costs of Production Schedule
K36: Projected
H37: =H$7 -> 2020 | I37: =I$7 -> 2021 | J37: =J$7 -> 2022 | K37: =K$7 -> 2023 | L37: =L$7 -> 2024 | M37: =M$7 -> 2025 | N37: =N$7 -> 2026 | O37: =O$7 -> 2027
B39: Annual Sales Volume | F39: (000's units) | J39: =J20 -> 344.47005 | K39: =K20 -> 361.69355 | L39: =L20 -> 376.16129 | M39: =M20 -> 391.20774 | N39: =N20 -> 406.85605 | O39: =O20 -> 420
B40: Cost Inflation | F40: (%) | L40: =L11 -> 0.02 | M40: =M11 -> 0.02 | N40: =N11 -> 0.025 | O40: =O11 -> 0.025
A42: 1 | B42: COSTS PER UNIT
C43: Variable Costs
D44: =Assumptions!C27 -> Raw Materials | F44: ($/unit) | K44: =Assumptions!E27 -> 226 | L44: =K44*(1+L40) -> 230.52 | M44: =L44*(1+M40) -> 235.1304 | N44: =M44*(1+N40) -> 241.00866 | O44: =N44*(1+O40) -> 247.03388
D45: =Assumptions!C28 -> Utilities | F45: ($/unit) | K45: =Assumptions!E28 -> 66.2 | L45: =K45*(1+L40) -> 67.524 | M45: =L45*(1+M40) -> 68.87448 | N45: =M45*(1+N40) -> 70.596342 | O45: =N45*(1+O40) -> 72.361251
D46: Total Variable Costs | F46: ($/unit) | K46: =K44+K45 -> 292.2 | L46: =L44+L45 -> 298.044 | M46: =M44+M45 -> 304.00488 | N46: =N44+N45 -> 311.605 | O46: =O44+O45 -> 319.39513
A48: 4 | C48: Fixed Costs
D49: =Assumptions!C29 -> Rent | F49: ($/unit) | K49: =K64*1000/K$39 -> 64.972129 | L49: =L64*1000/L$39 -> 63.722665 | M49: =M64*1000/M$39 -> 62.497229 | N49: =N64*1000/N$39 -> 61.595827 | O49: =O64*1000/O$39 -> 61.159883
D50: =Assumptions!C30 -> Operating Labour | F50: ($/unit) | K50: =K65*1000/K$39 -> 120.26756 | L50: =L65*1000/L$39 -> 117.95472 | M50: =M65*1000/M$39 -> 115.68636 | N50: =N65*1000/N$39 -> 114.01781 | O50: =O65*1000/O$39 -> 113.21085
D51: Other | F51: ($/unit) | K51: =K66*1000/K$39 -> 5.5295429 | L51: =L66*1000/L$39 -> 5.4232056 | M51: =M66*1000/M$39 -> 5.3189131 | N51: =N66*1000/N$39 -> 5.242198 | O51: =O66*1000/O$39 -> 5.2050964
D52: Total Fixed Costs | F52: ($/unit) | H52: OPERATING LEVERAGE | K52: =K49+K50+K51 -> 190.76923 | L52: =L49+L50+L51 -> 187.10059 | M52: =M49+M50+M51 -> 183.5025 | N52: =N49+N50+N51 -> 180.85583 | O52: =O49+O50+O51 -> 179.57583
C54: Total Costs | F54: ($/unit) | K54: =K52+K46 -> 482.96923 | L54: =L52+L46 -> 485.14459 | M54: =M52+M46 -> 487.50738 | N54: =N52+N46 -> 492.46083 | O54: =O52+O46 -> 498.97095
B57: COSTS IN MILLIONS
A58: 2 | C58: Variable Costs
D59: =D44 -> Raw Materials | F59: ($ MM) | K59: =(K44*K$39)/1000 -> 81.742742 | L59: =(L44*L$39)/1000 -> 86.712701 | M59: =(M44*M$39)/1000 -> 91.984833 | N59: =(N44*N$39)/1000 -> 98.055832 | O59: =(O44*O$39)/1000 -> 103.75423
...

Sheet Model (2)
O1: ="Currently Running : "&CHOOSE(Scenarios!$D$6,Scenarios!C14,Scenarios!C15,Scenarios!C16)&" Scenario" -> Currently Running : Base Case Scenario
B2: =Scenarios!B1 -> Blu Containers Company
B3: Revenue Schedule
H6: Historical data | K6: Projected
F7: Units | H7: =I7-1 -> 2020 | I7: =J7-1 -> 2021 | J7: =K7-1 -> 2022 | K7: =Scenarios!G6 -> 2023 | L7: =Scenarios!H6 -> 2024 | M7: =Scenarios!I6 -> 2025 | N7: =Scenarios!J6 -> 2026 | O7: =Scenarios!K6 -> 2027
B9: Pricing
C10: Gross Sales Price | F10: ($/unit) | J10: 694.4 | K10: =Scenarios!G23 -> 800 | L10: =Scenarios!H23 -> 725 | M10: =Scenarios!I23 -> 825 | N10: =Scenarios!J23 -> 800 | O10: =Scenarios!K23 -> 750
C11: Cost Inflation | F11: (%) | K11: =Scenarios!G12 -> 0.02 | L11: =Scenarios!H12 -> 0.02 | M11: =Scenarios!I12 -> 0.02 | N11: =Scenarios!J12 -> 0.025 | O11: =Scenarios!K12 -> 0.025
C12: Freight & Warehousing | F12: ($/unit) | J12: 100 | K12: =J12*(1+K11) -> 102 | L12: =K12*(1+L11) -> 104.04 | M12: =L12*(1+M11) -> 106.1208 | N12: =M12*(1+N11) -> 108.77382 | O12: =N12*(1+O11) -> 111.49317
C13: Net Sales Price | F13: ($/unit) | J13: =J10-J12 -> 594.4 | K13: =K10-K12 -> 698 | L13: =L10-L12 -> 620.96 | M13: =M10-M12 -> 718.8792 | N13: =N10-N12 -> 691.22618 | O13: =O10-O12 -> 638.50683
B16: Sales Volume
C17: Annual Factory Capacity | F17: (000's units) | K17: =Assumptions!N17 -> 420 | L17: =K17 -> 420 | M17: =L17 -> 420 | N17: =M17 -> 420 | O17: =N17 -> 420
C19: Sales Volume Growth | F19: (%) | K19: =Scenarios!G30 -> 0.05 | L19: =Scenarios!H30 -> 0.04 | M19: =Scenarios!I30 -> 0.04 | N19: =Scenarios!J30 -> 0.04 | O19: =Scenarios!K30 -> 0.04
C20: Annual Sales Volume | F20: (000's units) | J20: =J26*1000/J10 -> 344.47005 | K20: =MIN(J20*(K19+1),K17) -> 361.69355 | L20: =MIN(K20*(L19+1),L17) -> 376.16129 | M20: =MIN(L20*(M19+1),M17) -> 391.20774 | N20: =MIN(M20*(N19+1),N17) -> 406.85605 | O20: =MIN(N20*(O19+1),O17) -> 420
C22: Implied Operating Rate | K22: =K20/K17 -> 0.86117512 | L22: =L20/L17 -> 0.89562212 | M22: =M20/M17 -> 0.931447 | N22: =N20/N17 -> 0.96870488 | O22: =O20/O17 -> 1
B25: Revenue
C26: Gross Revenue | F26: ($ MM) | J26: =J83 -> 239.2 | K26: =(K10*K20)/1000 -> 289.35484 | L26: =(L10*L20)/1000 -> 272.71694 | M26: =(M10*M20)/1000 -> 322.74639 | N26: =(N10*N20)/1000 -> 325.48484 | O26: =(O10*O20)/1000 -> 315
C27: Freight & Warehousing | F27: ($ MM) | J27: =J84 -> 34.4 | K27: =(K12*K20)/1000 -> 36.892742 | L27: =(L12*L20)/1000 -> 39.135821 | M27: =(M12*M20)/1000 -> 41.515279 | N27: =(N12*N20)/1000 -> 44.255287 | O27: =(O12*O20)/1000 -> 46.82713
C28: Net Revenue | F28: ($ MM) | J28: =J26-J27 -> 204.8 | K28: =K26-K27 -> 252.4621 | L28: =L26-L27 -> 233.58111 | M28: =M26-M27 -> 281.23111 | N28: =N26-N27 -> 281.22955 | O28: =O26-O27 -> 268.17287
O31: =$O$1 -> Currently Running : Base Case Scenario
B32: =B$2 -> Blu Containers Company
B33: Costs of Production Schedule
K36: Projected
H37: =H$7 -> 2020 | I37: =I$7 -> 2021 | J37: =J$7 -> 2022 | K37: =K$7 -> 2023 | L37: =L$7 -> 2024 | M37: =M$7 -> 2025 | N37: =N$7 -> 2026 | O37: =O$7 -> 2027
B39: Annual Sales Volume | F39: (000's units) | J39: =J20 -> 344.47005 | K39: =K20 -> 361.69355 | L39: =L20 -> 376.16129 | M39: =M20 -> 391.20774 | N39: =N20 -> 406.85605 | O39: =O20 -> 420
B40: Cost Inflation | F40: (%) | L40: =L11 -> 0.02 | M40: =M11 -> 0.02 | N40: =N11 -> 0.025 | O40: =O11 -> 0.025
A42: 1 | B42: COSTS PER UNIT
C43: Variable Costs
D44: =Assumptions!C27 -> Raw Materials | F44: ($/unit) | K44: =Assumptions!E27 -> 226 | L44: =K44*(1+L40) -> 230.52 | M44: =L44*(1+M40) -> 235.1304 | N44: =M44*(1+N40) -> 241.00866 | O44: =N44*(1+O40) -> 247.03388
D45: =Assumptions!C28 -> Utilities | F45: ($/unit) | K45: =Assumptions!E28 -> 66.2 | L45: =K45*(1+L40) -> 67.524 | M45: =L45*(1+M40) -> 68.87448 | N45: =M45*(1+N40) -> 70.596342 | O45: =N45*(1+O40) -> 72.361251
D46: Total Variable Costs | F46: ($/unit) | K46: =K44+K45 -> 292.2 | L46: =L44+L45 -> 298.044 | M46: =M44+M45 -> 304.00488 | N46: =N44+N45 -> 311.605 | O46: =O44+O45 -> 319.39513
A48: 4 | C48: Fixed Costs
D49: =Assumptions!C29 -> Rent | F49: ($/unit) | K49: =K64*1000/K$39 -> 64.972129 | L49: =L64*1000/L$39 -> 63.722665 | M49: =M64*1000/M$39 -> 62.497229 | N49: =N64*1000/N$39 -> 61.595827 | O49: =O64*1000/O$39 -> 61.159883
D50: =Assumptions!C30 -> Operating Labour | F50: ($/unit) | K50: =K65*1000/K$39 -> 120.26756 | L50: =L65*1000/L$39 -> 117.95472 | M50: =M65*1000/M$39 -> 115.68636 | N50: =N65*1000/N$39 -> 114.01781 | O50: =O65*1000/O$39 -> 113.21085
D51: Other | F51: ($/unit) | K51: =K66*1000/K$39 -> 5.5295429 | L51: =L66*1000/L$39 -> 5.4232056 | M51: =M66*1000/M$39 -> 5.3189131 | N51: =N66*1000/N$39 -> 5.242198 | O51: =O66*1000/O$39 -> 5.2050964
D52: Total Fixed Costs | F52: ($/unit) | H52: OPERATING LEVERAGE | K52: =K49+K50+K51 -> 190.76923 | L52: =L49+L50+L51 -> 187.10059 | M52: =M49+M50+M51 -> 183.5025 | N52: =N49+N50+N51 -> 180.85583 | O52: =O49+O50+O51 -> 179.57583
C54: Total Costs | F54: ($/unit) | K54: =K52+K46 -> 482.96923 | L54: =L52+L46 -> 485.14459 | M54: =M52+M46 -> 487.50738 | N54: =N52+N46 -> 492.46083 | O54: =O52+O46 -> 498.97095
B57: COSTS IN MILLIONS
A58: 2 | C58: Variable Costs
D59: =D44 -> Raw Materials | F59: ($ MM) | K59: =(K44*K$39)/1000 -> 81.742742 | L59: =(L44*L$39)/1000 -> 86.712701 | M59: =(M44*M$39)/1000 -> 91.984833 | N59: =(N44*N$39)/1000 -> 98.055832 | O59: =(O44*O$39)/1000 -> 103.75423
...

Sheet Sheet1
D12: Custom formating
D13: click on customised tab , the number is still a number and can be used in calculation
E14: 4.5
E15: 25
D16: to format cell to pos, neg, zero, text
E17: 65
E18: -65
E19: 0
E20: fjjgk
D21: Backing into fixed and variable
D22: you might just know that last year variable costs were 75% of the total
G23: 2022A | H23: 2023
F24: Price - $/unit | G24: 800 | H24: 800
F25: unit growth | H25: 0.03
F26: Units (000s) | G26: =G27*1000/G24 -> 125 | H26: =G26*(1+H25) -> 128.75
F27: Revenue - $MM | G27: 100 | H27: =H24*H26/1000 -> 103
F28: Revenue frowth
F29: Inflation | H29: 0.025
F30: Variable cost % | G30: 0.75
F31: Fixed cost % | G31: =1-G30 -> 0.25
F33: Variable cost - $/unit | G33: =G37*1000/G26 -> 360 | H33: =G33*(1+H29) -> 369 | I33: 1
F34: Fixed cost - $/unit | G34: =G38*1000/G26 -> 120 | H34: =H38*1000/H26 -> 119.41748 | I34: 4
F35: total cost - $/unit | G35: =G33+G34 -> 480 | H35: =H33+H34 -> 488.41748
F37: Variable cost - $MM | G37: =G30*G41 -> 45 | H37: =H33*H26/1000 -> 47.50875 | I37: 2
F38: Fixed cost - $MM | G38: =G31*G41 -> 15 | H38: =G38*(1+H29) -> 15.375 | I38: 3
F39: total cost - $MM | G39: =G37+G38 -> 60 | H39: =H37+H38 -> 62.88375
F41: operating costs | G41: 60 | H41: =H39 -> 62.88375
F42: gross profit | G42: 40 | H42: =H27-H41 -> 40.11625
F43: profit increase | H43: =H42/G42-1 -> 0.00290625
F45: profit margin | G45: =G42/G27 -> 0.4 | H45: =H42/H27 -> 0.38947816
D47: Capturing the operating leverage
D48: how do we know if a company is experiencing operating leverage
G50: 2022A | H50: 2023
F51: Annual growth | H51: =H52/G52-1 -> 0.05
F52: Revenue | G52: 100 | H52: 105
F54: Operating costs | G54: 60 | H54: 63
F55: Gross profit | G55: =G52-G54 -> 40 | H55: =H52-H54 -> 42
F57: profit margin | G57: =G55/G52 -> 0.4 | H57: =H55/H52 -> 0.4
D59: if you forecast the ,argin and keep it constant; what does that assume about the costs ?
D60: this assumes that ALL the costs at the company are variable
...

Sheet Scenarios (2)
B1: =Assumptions!B1 -> Blu Containers Company
B2: Economic and Sales Scenarios
B6: SCENARIO SWITCH: | D6: 2 | G6: =Assumptions!G8 -> 2023 | H6: =G6+1 -> 2024 | I6: =H6+1 -> 2025 | J6: =I6+1 -> 2026 | K6: =J6+1 -> 2027
D9: Base Case
B10: ECONOMIC SCENARIOS
B12: Cost Inflation | D12: LIVE CASE -> | G12: =CHOOSE($D$6,G14,G15,G16) -> 0.018 | H12: =CHOOSE(MATCH($D$9,$C$14:$C$16,0),H14,H15,H16) -> 0.02 | I12: =INDEX(I14:I16,$D$6) -> 0.018 | J12: =INDEX(J14:J16,$D$6) -> 0.02 | K12: =INDEX(K14:K16,$D$6) -> 0.02
C14: =Assumptions!C18 -> Base Case | D14: step1 | G14: 0.02 | H14: 0.02 | I14: 0.02 | J14: 0.025 | K14: 0.025
C15: =Assumptions!C19 -> Best Case | D15: inputs | G15: 0.018 | H15: 0.018 | I15: 0.018 | J15: 0.02 | K15: 0.02
C16: =Assumptions!C20 -> Worst Case | D16: blue | G16: 0.025 | H16: 0.025 | I16: 0.025 | J16: 0.025 | K16: 0.025
B21: SALES SCENARIOS
B23: Sales Price - $/Unit | D23: 1 | G23: =CHOOSE($D$23,G25,G26,G27) -> 800 | H23: =CHOOSE($D$23,H25,H26,H27) -> 725 | I23: =CHOOSE($D$23,I25,I26,I27) -> 825 | J23: =CHOOSE($D$23,J25,J26,J27) -> 800 | K23: =CHOOSE($D$23,K25,K26,K27) -> 750
C25: =C14 -> Base Case | G25: 800 | H25: 725 | I25: 825 | J25: 800 | K25: 750
A26: =Assumptions!F19 -> 0.04 | G26: =G25*(1+$A26) -> 832 | H26: =H25*(1+$A26) -> 754 | I26: =I25*(1+$A26) -> 858 | J26: =J25*(1+$A26) -> 832 | K26: =K25*(1+$A26) -> 780
A27: =Assumptions!F20 -> -0.04 | G27: =G25*(1+$A27) -> 768 | H27: =H25*(1+$A27) -> 696 | I27: =I25*(1+$A27) -> 792 | J27: =J25*(1+$A27) -> 768 | K27: =K25*(1+$A27) -> 720
B30: Sales Volume Growth | D30: 1 | G30: =CHOOSE($D$30,G32,G33,G34) -> 0.05 | H30: =CHOOSE($D$30,H32,H33,H34) -> 0.04 | I30: =CHOOSE($D$30,I32,I33,I34) -> 0.04 | J30: =CHOOSE($D$30,J32,J33,J34) -> 0.04 | K30: =CHOOSE($D$30,K32,K33,K34) -> 0.04
C32: =C14 -> Base Case | G32: 0.05 | H32: 0.04 | I32: 0.04 | J32: 0.04 | K32: 0.04
C33: =C15 -> Best Case | G33: 0.05 | H33: 0.04 | I33: 0.05 | J33: 0.05 | K33: 0.04
C34: =C16 -> Worst Case | G34: 0.04 | H34: 0.04 | I34: 0.03 | J34: 0.03 | K34: 0.02
